Workbook

Sheet cnpj
A1: Cod_Lotação | B1: CNPJ
A2: 8982
A3: 9059
A4: 9083
A5: 9121
A6: 9130
A7: 9210
A8: 9326 | B8: 02.455.519/0001-90
A9: 9385
A10: 9393 | B10: 03.049.222/0001-97
A11: 9415 | B11: 3143474000180
A12: 9423 | B12: 1996502000187
A13: 9440 | B13: 02.010.853/0001-30
A14: 9466 | B14: 15037757000127
A15: 9474 | B15: 01.939.513/0001-25
A16: 9482 | B16: 02.517.515/0001-99
A17: 9520 | B17: 02.315.622/0001-34
A18: 9539 | B18: 03.358.621/0001-30
A19: 9547 | B19: 01.967.817/0001-04
A20: 9571 | B20: 03.087.642/0001-68
A21: 9610 | B21: 03.597.780/0001-97
A22: 9652 | B22: 03.295.686/0001-83
A23: 9679 | B23: 01.586.615/0001-04
A24: 9687 | B24: 03.159.021/0001-42
A25: 9695 | B25: 02225544/0001/87
A26: 9709 | B26: 03.165.188/0001-16
... A29: 9733 | B29: 02.010.854/0001-84
A30: 9750
A31: 9784
A32: 9806 | B32: 01.606.944/0001-70
A33: 9814 | B33: 02.471.496/0001-07
A34: 9830 | B34: 03.159.030/0001-33
A35: 9849 | B35: 01.944.536/0001-28
A36: 9857 | B36: 14.925.622/0001-35
A37: 9865 | B37: 03.146.565/0001-70
A38: 9903 | B38: 02.493.957/0001-42
A39: 9911 | B39: 02.274.833/0001-76
A40: 9920 | B40: 03.225.549/0001-72
A41: 9938 | B41: 02.030.988/0001-67
A42: 9946 | B42: 03.186.262/0001-80
...

Sheet sisgi
A1: id_lotacao
A2: 9326
A3: 9393
A4: 9440
A5: 9474
A6: 9482
A7: 9520
A8: 9539
A9: 9547
A10: 9571
A11: 9610
A12: 9652
A13: 9679
... A645: 946079

Sheet sisgi_cnpj
A1: id_lotacao | B1: CNPJ_original | C1: CNPJ_14_digitos | D1: CNPJ_padronizado | E1: status | G1: Resumo | H1: Qtde
A2: =sisgi!A2 -> 9326 | B2: =IFERROR(IF(INDEX(cnpj!$B:$B,MATCH(A2,cnpj!$A:$A,0))="","",INDEX(cnpj!$B:$B,MATCH(A2,cnpj!$A:$A,0))),"") -> 02.455.519/0001-90 | C2: =IF(B2="","",RIGHT("00000000000000"&SUBSTITUTE(SUBSTITUTE(SUBSTITUTE(SUBSTITUTE(B2,".",""),"/",""),"-","")," ",""),14)) -> 02455519000190 | D2: =IF(C2="","",MID(C2,1,2)&"."&MID(C2,3,3)&"."&MID(C2,6,3)&"/"&MID(C2,9,4)&"-"&MID(C2,13,2)) -> 02.455.519/0001-90 | E2: =IF(ISNA(MATCH(A2,cnpj!$A:$A,0)),"Lotação não existe na aba cnpj",IF(B2="","Sem CNPJ na aba cnpj","OK")) -> OK | G2: Lotações no sisgi | H2: =COUNTA(A2:A645) -> 644
A3: =sisgi!A3 -> 9393 | B3: =IFERROR(IF(INDEX(cnpj!$B:$B,MATCH(A3,cnpj!$A:$A,0))="","",INDEX(cnpj!$B:$B,MATCH(A3,cnpj!$A:$A,0))),"") -> 03.049.222/0001-97 | C3: =IF(B3="","",RIGHT("00000000000000"&SUBSTITUTE(SUBSTITUTE(SUBSTITUTE(SUBSTITUTE(B3,".",""),"/",""),"-","")," ",""),14)) -> 03049222000197 | D3: =IF(C3="","",MID(C3,1,2)&"."&MID(C3,3,3)&"."&MID(C3,6,3)&"/"&MID(C3,9,4)&"-"&MID(C3,13,2)) -> 03.049.222/0001-97 | E3: =IF(ISNA(MATCH(A3,cnpj!$A:$A,0)),"Lotação não existe na aba cnpj",IF(B3="","Sem CNPJ na aba cnpj","OK")) -> OK | G3: Com CNPJ encontrado | H3: =COUNTIF(E2:E645,"OK") -> 643
A4: =sisgi!A4 -> 9440 | B4: =IFERROR(IF(INDEX(cnpj!$B:$B,MATCH(A4,cnpj!$A:$A,0))="","",INDEX(cnpj!$B:$B,MATCH(A4,cnpj!$A:$A,0))),"") -> 02.010.853/0001-30 | C4: =IF(B4="","",RIGHT("00000000000000"&SUBSTITUTE(SUBSTITUTE(SUBSTITUTE(SUBSTITUTE(B4,".",""),"/",""),"-","")," ",""),14)) -> 02010853000130 | D4: =IF(C4="","",MID(C4,1,2)&"."&MID(C4,3,3)&"."&MID(C4,6,3)&"/"&MID(C4,9,4)&"-"&MID(C4,13,2)) -> 02.010.853/0001-30 | E4: =IF(ISNA(MATCH(A4,cnpj!$A:$A,0)),"Lotação não existe na aba cnpj",IF(B4="","Sem CNPJ na aba cnpj","OK")) -> OK | G4: Sem CNPJ na aba cnpj | H4: =COUNTIF(E2:E645,"Sem CNPJ*") -> 0
A5: =sisgi!A5 -> 9474 | B5: =IFERROR(IF(INDEX(cnpj!$B:$B,MATCH(A5,cnpj!$A:$A,0))="","",INDEX(cnpj!$B:$B,MATCH(A5,cnpj!$A:$A,0))),"") -> 01.939.513/0001-25 | C5: =IF(B5="","",RIGHT("00000000000000"&SUBSTITUTE(SUBSTITUTE(SUBSTITUTE(SUBSTITUTE(B5,".",""),"/",""),"-","")," ",""),14)) -> 01939513000125 | D5: =IF(C5="","",MID(C5,1,2)&"."&MID(C5,3,3)&"."&MID(C5,6,3)&"/"&MID(C5,9,4)&"-"&MID(C5,13,2)) -> 01.939.513/0001-25 | E5: =IF(ISNA(MATCH(A5,cnpj!$A:$A,0)),"Lotação não existe na aba cnpj",IF(B5="","Sem CNPJ na aba cnpj","OK")) -> OK | G5: Lotação não existe na aba cnpj | H5: =COUNTIF(E2:E645,"Lotação não*") -> 1
A6: =sisgi!A6 -> 9482 | B6: =IFERROR(IF(INDEX(cnpj!$B:$B,MATCH(A6,cnpj!$A:$A,0))="","",INDEX(cnpj!$B:$B,MATCH(A6,cnpj!$A:$A,0))),"") -> 02.517.515/0001-99 | C6: =IF(B6="","",RIGHT("00000000000000"&SUBSTITUTE(SUBSTITUTE(SUBSTITUTE(SUBSTITUTE(B6,".",""),"/",""),"-","")," ",""),14)) -> 02517515000199 | D6: =IF(C6="","",MID(C6,1,2)&"."&MID(C6,3,3)&"."&MID(C6,6,3)&"/"&MID(C6,9,4)&"-"&MID(C6,13,2)) -> 02.517.515/0001-99 | E6: =IF(ISNA(MATCH(A6,cnpj!$A:$A,0)),"Lotação não existe na aba cnpj",IF(B6="","Sem CNPJ na aba cnpj","OK")) -> OK
A7: =sisgi!A7 -> 9520 | B7: =IFERROR(IF(INDEX(cnpj!$B:$B,MATCH(A7,cnpj!$A:$A,0))="","",INDEX(cnpj!$B:$B,MATCH(A7,cnpj!$A:$A,0))),"") -> 02.315.622/0001-34 | C7: =IF(B7="","",RIGHT("00000000000000"&SUBSTITUTE(SUBSTITUTE(SUBSTITUTE(SUBSTITUTE(B7,".",""),"/",""),"-","")," ",""),14)) -> 02315622000134 | D7: =IF(C7="","",MID(C7,1,2)&"."&MID(C7,3,3)&"."&MID(C7,6,3)&"/"&MID(C7,9,4)&"-"&MID(C7,13,2)) -> 02.315.622/0001-34 | E7: =IF(ISNA(MATCH(A7,cnpj!$A:$A,0)),"Lotação não existe na aba cnpj",IF(B7="","Sem CNPJ na aba cnpj","OK")) -> OK
A8: =sisgi!A8 -> 9539 | B8: =IFERROR(IF(INDEX(cnpj!$B:$B,MATCH(A8,cnpj!$A:$A,0))="","",INDEX(cnpj!$B:$B,MATCH(A8,cnpj!$A:$A,0))),"") -> 03.358.621/0001-30 | C8: =IF(B8="","",RIGHT("00000000000000"&SUBSTITUTE(SUBSTITUTE(SUBSTITUTE(SUBSTITUTE(B8,".",""),"/",""),"-","")," ",""),14)) -> 03358621000130 | D8: =IF(C8="","",MID(C8,1,2)&"."&MID(C8,3,3)&"."&MID(C8,6,3)&"/"&MID(C8,9,4)&"-"&MID(C8,13,2)) -> 03.358.621/0001-30 | E8: =IF(ISNA(MATCH(A8,cnpj!$A:$A,0)),"Lotação não existe na aba cnpj",IF(B8="","Sem CNPJ na aba cnpj","OK")) -> OK
A9: =sisgi!A9 -> 9547 | B9: =IFERROR(IF(INDEX(cnpj!$B:$B,MATCH(A9,cnpj!$A:$A,0))="","",INDEX(cnpj!$B:$B,MATCH(A9,cnpj!$A:$A,0))),"") -> 01.967.817/0001-04 | C9: =IF(B9="","",RIGHT("00000000000000"&SUBSTITUTE(SUBSTITUTE(SUBSTITUTE(SUBSTITUTE(B9,".",""),"/",""),"-","")," ",""),14)) -> 01967817000104 | D9: =IF(C9="","",MID(C9,1,2)&"."&MID(C9,3,3)&"."&MID(C9,6,3)&"/"&MID(C9,9,4)&"-"&MID(C9,13,2)) -> 01.967.817/0001-04 | E9: =IF(ISNA(MATCH(A9,cnpj!$A:$A,0)),"Lotação não existe na aba cnpj",IF(B9="","Sem CNPJ na aba cnpj","OK")) -> OK
A10: =sisgi!A10 -> 9571 | B10: =IFERROR(IF(INDEX(cnpj!$B:$B,MATCH(A10,cnpj!$A:$A,0))="","",INDEX(cnpj!$B:$B,MATCH(A10,cnpj!$A:$A,0))),"") -> 03.087.642/0001-68 | C10: =IF(B10="","",RIGHT("00000000000000"&SUBSTITUTE(SUBSTITUTE(SUBSTITUTE(SUBSTITUTE(B10,".",""),"/",""),"-","")," ",""),14)) -> 03087642000168 | D10: =IF(C10="","",MID(C10,1,2)&"."&MID(C10,3,3)&"."&MID(C10,6,3)&"/"&MID(C10,9,4)&"-"&MID(C10,13,2)) -> 03.087.642/0001-68 | E10: =IF(ISNA(MATCH(A10,cnpj!$A:$A,0)),"Lotação não existe na aba cnpj",IF(B10="","Sem CNPJ na aba cnpj","OK")) -> OK
A11: =sisgi!A11 -> 9610 | B11: =IFERROR(IF(INDEX(cnpj!$B:$B,MATCH(A11,cnpj!$A:$A,0))="","",INDEX(cnpj!$B:$B,MATCH(A11,cnpj!$A:$A,0))),"") -> 03.597.780/0001-97 | C11: =IF(B11="","",RIGHT("00000000000000"&SUBSTITUTE(SUBSTITUTE(SUBSTITUTE(SUBSTITUTE(B11,".",""),"/",""),"-","")," ",""),14)) -> 03597780000197 | D11: =IF(C11="","",MID(C11,1,2)&"."&MID(C11,3,3)&"."&MID(C11,6,3)&"/"&MID(C11,9,4)&"-"&MID(C11,13,2)) -> 03.597.780/0001-97 | E11: =IF(ISNA(MATCH(A11,cnpj!$A:$A,0)),"Lotação não existe na aba cnpj",IF(B11="","Sem CNPJ na aba cnpj","OK")) -> OK
A12: =sisgi!A12 -> 9652 | B12: =IFERROR(IF(INDEX(cnpj!$B:$B,MATCH(A12,cnpj!$A:$A,0))="","",INDEX(cnpj!$B:$B,MATCH(A12,cnpj!$A:$A,0))),"") -> 03.295.686/0001-83 | C12: =IF(B12="","",RIGHT("00000000000000"&SUBSTITUTE(SUBSTITUTE(SUBSTITUTE(SUBSTITUTE(B12,".",""),"/",""),"-","")," ",""),14)) -> 03295686000183 | D12: =IF(C12="","",MID(C12,1,2)&"."&MID(C12,3,3)&"."&MID(C12,6,3)&"/"&MID(C12,9,4)&"-"&MID(C12,13,2)) -> 03.295.686/0001-83 | E12: =IF(ISNA(MATCH(A12,cnpj!$A:$A,0)),"Lotação não existe na aba cnpj",IF(B12="","Sem CNPJ na aba cnpj","OK")) -> OK
A13: =sisgi!A13 -> 9679 | B13: =IFERROR(IF(INDEX(cnpj!$B:$B,MATCH(A13,cnpj!$A:$A,0))="","",INDEX(cnpj!$B:$B,MATCH(A13,cnpj!$A:$A,0))),"") -> 01.586.615/0001-04 | C13: =IF(B13="","",RIGHT("00000000000000"&SUBSTITUTE(SUBSTITUTE(SUBSTITUTE(SUBSTITUTE(B13,".",""),"/",""),"-","")," ",""),14)) -> 01586615000104 | D13: =IF(C13="","",MID(C13,1,2)&"."&MID(C13,3,3)&"."&MID(C13,6,3)&"/"&MID(C13,9,4)&"-"&MID(C13,13,2)) -> 01.586.615/0001-04 | E13: =IF(ISNA(MATCH(A13,cnpj!$A:$A,0)),"Lotação não existe na aba cnpj",IF(B13="","Sem CNPJ na aba cnpj","OK")) -> OK
A14: =sisgi!A14 -> 9687 | B14: =IFERROR(IF(INDEX(cnpj!$B:$B,MATCH(A14,cnpj!$A:$A,0))="","",INDEX(cnpj!$B:$B,MATCH(A14,cnpj!$A:$A,0))),"") -> 03.159.021/0001-42 | C14: =IF(B14="","",RIGHT("00000000000000"&SUBSTITUTE(SUBSTITUTE(SUBSTITUTE(SUBSTITUTE(B14,".",""),"/",""),"-","")," ",""),14)) -> 03159021000142 | D14: =IF(C14="","",MID(C14,1,2)&"."&MID(C14,3,3)&"."&MID(C14,6,3)&"/"&MID(C14,9,4)&"-"&MID(C14,13,2)) -> 03.159.021/0001-42 | E14: =IF(ISNA(MATCH(A14,cnpj!$A:$A,0)),"Lotação não existe na aba cnpj",IF(B14="","Sem CNPJ na aba cnpj","OK")) -> OK
A15: =sisgi!A15 -> 9709 | B15: =IFERROR(IF(INDEX(cnpj!$B:$B,MATCH(A15,cnpj!$A:$A,0))="","",INDEX(cnpj!$B:$B,MATCH(A15,cnpj!$A:$A,0))),"") -> 03.165.188/0001-16 | C15: =IF(B15="","",RIGHT("00000000000000"&SUBSTITUTE(SUBSTITUTE(SUBSTITUTE(SUBSTITUTE(B15,".",""),"/",""),"-","")," ",""),14)) -> 03165188000116 | D15: =IF(C15="","",MID(C15,1,2)&"."&MID(C15,3,3)&"."&MID(C15,6,3)&"/"&MID(C15,9,4)&"-"&MID(C15,13,2)) -> 03.165.188/0001-16 | E15: =IF(ISNA(MATCH(A15,cnpj!$A:$A,0)),"Lotação não existe na aba cnpj",IF(B15="","Sem CNPJ na aba cnpj","OK")) -> OK
A16: =sisgi!A16 -> 9717 | B16: =IFERROR(IF(INDEX(cnpj!$B:$B,MATCH(A16,cnpj!$A:$A,0))="","",INDEX(cnpj!$B:$B,MATCH(A16,cnpj!$A:$A,0))),"") -> 02.051.792/0001-59 | C16: =IF(B16="","",RIGHT("00000000000000"&SUBSTITUTE(SUBSTITUTE(SUBSTITUTE(SUBSTITUTE(B16,".",""),"/",""),"-","")," ",""),14)) -> 02051792000159 | D16: =IF(C16="","",MID(C16,1,2)&"."&MID(C16,3,3)&"."&MID(C16,6,3)&"/"&MID(C16,9,4)&"-"&MID(C16,13,2)) -> 02.051.792/0001-59 | E16: =IF(ISNA(MATCH(A16,cnpj!$A:$A,0)),"Lotação não existe na aba cnpj",IF(B16="","Sem CNPJ na aba cnpj","OK")) -> OK
A17: =sisgi!A17 -> 9725 | B17: =IFERROR(IF(INDEX(cnpj!$B:$B,MATCH(A17,cnpj!$A:$A,0))="","",INDEX(cnpj!$B:$B,MATCH(A17,cnpj!$A:$A,0))),"") -> 02.443.825/0001-06 | C17: =IF(B17="","",RIGHT("00000000000000"&SUBSTITUTE(SUBSTITUTE(SUBSTITUTE(SUBSTITUTE(B17,".",""),"/",""),"-","")," ",""),14)) -> 02443825000106 | D17: =IF(C17="","",MID(C17,1,2)&"."&MID(C17,3,3)&"."&MID(C17,6,3)&"/"&MID(C17,9,4)&"-"&MID(C17,13,2)) -> 02.443.825/0001-06 | E17: =IF(ISNA(MATCH(A17,cnpj!$A:$A,0)),"Lotação não existe na aba cnpj",IF(B17="","Sem CNPJ na aba cnpj","OK")) -> OK
... A645: =sisgi!A645 -> 946079 | B645: =IFERROR(IF(INDEX(cnpj!$B:$B,MATCH(A645,cnpj!$A:$A,0))="","",INDEX(cnpj!$B:$B,MATCH(A645,cnpj!$A:$A,0))),"") -> 66.928.971/0001-04 | C645: =IF(B645="","",RIGHT("00000000000000"&SUBSTITUTE(SUBSTITUTE(SUBSTITUTE(SUBSTITUTE(B645,".",""),"/",""),"-","")," ",""),14)) -> 66928971000104 | D645: =IF(C645="","",MID(C645,1,2)&"."&MID(C645,3,3)&"."&MID(C645,6,3)&"/"&MID(C645,9,4)&"-"&MID(C645,13,2)) -> 66.928.971/0001-04 | E645: =IF(ISNA(MATCH(A645,cnpj!$A:$A,0)),"Lotação não existe na aba cnpj",IF(B645="","Sem CNPJ na aba cnpj","OK")) -> OK
